<?xml version="1.0"?>

<sdf version='1.6'>
  <model name='TinyRobot'>
    <plugin name="slotcar" filename="libslotcar.so">

      <nominal_drive_speed>0.5</nominal_drive_speed>
      <nominal_drive_acceleration>0.25</nominal_drive_acceleration>
      <max_drive_acceleration>0.75</max_drive_acceleration>

      <nominal_turn_speed>0.6</nominal_turn_speed>
      <nominal_turn_acceleration>1.5</nominal_turn_acceleration>
      <max_turn_acceleration>2.0</max_turn_acceleration>

      <tire_radius>0.1</tire_radius>
      <base_width>0.3206</base_width>

      <stop_distance>0.75</stop_distance>
      <stop_radius>0.75</stop_radius>

      <!-- Can the robot drive backwards -->
      <reversible>true</reversible>

      <!-- Battery params -->
      <nominal_voltage>12.0</nominal_voltage>
      <nominal_capacity>24.0</nominal_capacity>
      <charging_current>5.0</charging_current>

      <!-- Physical params -->
      <mass>20.0</mass>
      <inertia>10.0</inertia>
      <friction_coefficient>0.22</friction_coefficient>

      <!-- Power systems -->
      <nominal_power>20.0</nominal_power>

    </plugin>

    <link name='base_footprint'>
      <pose frame=''>0 0 0 0 -0 0</pose>
      <inertial>
        <pose frame=''>-0.15 0 0.13 0 -0 0</pose>
        <mass>7</mass> <!-- A higher mass causes wheels to spin while attempting to turn when using DART -->
        <inertia>
          <ixx>0.0594508</ixx>
          <ixy>0</ixy>
          <ixz>-2.77556e-17</ixz>
          <iyy>0.150753</iyy>
          <iyz>0</iyz>
          <izz>0.172704</izz>
        </inertia>
      </inertial>
      <collision name='base_footprint_fixed_joint_lump__base_link_collision'>
        <pose frame=''>-0.11 0 0.151 0 -0 0</pose>
        <geometry>
          <box>
            <size>0.398 0.268 0.16</size>
          </box>
        </geometry>
      </collision>
      <collision name='base_footprint_fixed_joint_lump__base_link_collision_1'>
        <pose frame=''>-0.136 0 0.248 0 -0 0</pose>
        <geometry>
          <box>
            <size>0.375 0.268 0.034</size>
          </box>
        </geometry>
      </collision>
      <collision name='base_footprint_fixed_joint_lump__base_link_collision_2'>
        <pose frame=''>-0.279 0.169 0.106 0 -0 0</pose>
        <geometry>
          <box>
            <size>0.1 0.07 0.07</size>
          </box>
        </geometry>
      </collision>
      <collision name='base_footprint_fixed_joint_lump__base_link_collision_3'>
        <pose frame=''>-0.279 -0.169 0.106 0 -0 0</pose>
        <geometry>
          <box>
            <size>0.1 0.07 0.07</size>
          </box>
        </geometry>
      </collision>
      <collision name='base_footprint_fixed_joint_lump__left_caster_wheel_collision_4'>
        <pose frame=''>-0.3 0.169 0.04 0 -0 0</pose>
        <geometry>
          <sphere>
            <radius>0.04</radius>
          </sphere>
        </geometry>
        <surface>
          <contact>
            <ode>
              <kp>1e+08</kp>
              <min_depth>0.005</min_depth>
            </ode>
          </contact>
          <friction>
            <ode>
              <mu>0</mu>
              <mu2>0</mu2>
            </ode>
          </friction>
        </surface>
      </collision>
      <collision name='base_footprint_fixed_joint_lump__raspicam_collision_5'>
        <pose frame=''>0.05 0.085 0.245 0 -1.15192 3.1415</pose>
        <geometry>
          <box>
            <size>0.03 0.026 0.016</size>
          </box>
        </geometry>
      </collision>
      <collision name='base_footprint_fixed_joint_lump__right_caster_wheel_collision_6'>
        <pose frame=''>-0.3 -0.169 0.04 0 -0 0</pose>
        <geometry>
          <sphere>
            <radius>0.04</radius>
          </sphere>
        </geometry>
        <surface>
          <contact>
            <ode>
              <kp>1e+08</kp>
              <min_depth>0.005</min_depth>
            </ode>
          </contact>
          <friction>
            <ode>
              <mu>0</mu>
              <mu2>0</mu2>
            </ode>
          </friction>
        </surface>
      </collision>
      <collision name='base_footprint_fixed_joint_lump__sonar_0_collision_7'>
        <pose frame=''>0.01 -0.14 0.25 0 0 -1.5708</pose>
        <geometry>
          <box>
            <size>0.02 0.044 0.021</size>
          </box>
        </geometry>
        <surface>
          <contact>
            <ode/>
          </contact>
          <friction>
            <ode/>
          </friction>
        </surface>
      </collision>
      <collision name='base_footprint_fixed_joint_lump__sonar_1_collision_8'>
        <pose frame=''>0.08 -0.07 0.25 0 -0 0.785</pose>
        <geometry>
          <box>
            <size>0.02 0.044 0.021</size>
          </box>
        </geometry>
        <surface>
          <contact>
            <ode/>
          </contact>
          <friction>
            <ode/>
          </friction>
        </surface>
      </collision>
      <collision name='base_footprint_fixed_joint_lump__sonar_2_collision_9'>
        <pose frame=''>0.08 -0.01 0.25 0 0 -0.785</pose>
        <geometry>
          <box>
            <size>0.02 0.044 0.021</size>
          </box>
        </geometry>
        <surface>
          <contact>
            <ode/>
          </contact>
          <friction>
            <ode/>
          </friction>
        </surface>
      </collision>
      <collision name='base_footprint_fixed_joint_lump__sonar_3_collision_10'>
        <pose frame=''>0.08 0.04 0.25 0 -0 0</pose>
        <geometry>
          <box>
            <size>0.02 0.044 0.021</size>
          </box>
        </geometry>
        <surface>
          <contact>
            <ode/>
          </contact>
          <friction>
            <ode/>
          </friction>
        </surface>
      </collision>
      <collision name='base_footprint_fixed_joint_lump__sonar_4_collision_11'>
        <pose frame=''>0.01 0.14 0.25 0 -0 1.5708</pose>
        <geometry>
          <box>
            <size>0.02 0.044 0.021</size>
          </box>
        </geometry>
        <surface>
          <contact>
            <ode/>
          </contact>
          <friction>
            <ode/>
          </friction>
        </surface>
      </collision>
      <visual name='base_footprint_fixed_joint_lump__base_link_visual'>
        <pose frame=''>-0.11 0 0.071 0 -0 0</pose>
        <geometry>
          <mesh>
            <scale>1 1 1</scale>
            <uri>model://TinyRobot/meshes/tinyRobot_body.dae</uri>
          </mesh>
        </geometry>
      </visual>
      <visual name='base_footprint_fixed_joint_lump__base_link_visual_1'>
        <pose frame=''>-0.279 0.17 0.09 0 -0 -3.14159</pose>
        <geometry>
          <mesh>
            <scale>1 1 1</scale>
            <uri>model://TinyRobot/meshes/caster_wheel.dae</uri>
          </mesh>
        </geometry>
      </visual>
      <visual name='base_footprint_fixed_joint_lump__base_link_visual_2'>
        <pose frame=''>-0.279 -0.17 0.09 0 -0 -3.14159</pose>
        <geometry>
          <mesh>
            <scale>1 1 1</scale>
            <uri>model://TinyRobot/meshes/caster_wheel.dae</uri>
          </mesh>
        </geometry>
      </visual>
      <velocity_decay/>
      <velocity_decay/>
      <velocity_decay/>
      <velocity_decay/>
    </link>
    <link name='left_wheel'>
      <pose frame=''>0 0.163 0.1 0 -0 1.5708</pose>
      <inertial>
        <pose frame=''>0 0 0 3.14159 1.57079 3.14159</pose>
        <mass>3.34</mass>
        <inertia>
          <ixx>0.00904583</ixx>
          <ixy>0</ixy>
          <ixz>0</ixz>
          <iyy>0.00904583</iyy>
          <iyz>0</iyz>
          <izz>0.0167</izz>
        </inertia>
      </inertial>
      <collision name='left_wheel_collision'>
        <pose frame=''>0 0 0 3.14159 1.57079 3.14159</pose>
        <geometry>
          <sphere>
            <radius>0.1</radius>
          </sphere>
        </geometry>
        <surface>
          <contact>
            <ode>
            <!--
              <kp>1e+08</kp>
              <min_depth>0.005</min_depth>
              -->
              <kp>10000000.0</kp>
              <kd>1.0</kd>
            </ode>
          </contact>
          <friction>
            <ode>
              <mu>1</mu>
              <mu2>1</mu2>
              <fdir1>0 0 1</fdir1>
            </ode>
          </friction>
        </surface>
      </collision>
      <visual name='left_wheel_visual'>
        <pose frame=''>-0.071 0 0 0 -0 0</pose>
        <geometry>
          <mesh>
            <scale>1 1 1</scale>
            <uri>model://TinyRobot/meshes/front_wheel.dae</uri>
          </mesh>
        </geometry>
      </visual>
      <gravity>1</gravity>
      <velocity_decay/>
    </link>
    <joint name='joint_tire_left' type='revolute'>
      <child>left_wheel</child>
      <parent>base_footprint</parent>
      <axis>
        <xyz>0 1 0</xyz>
        <limit>
          <lower>-1e+16</lower>
          <upper>1e+16</upper>
        </limit>
        <dynamics>
          <spring_reference>0</spring_reference>
          <spring_stiffness>0</spring_stiffness>
        </dynamics>
        <use_parent_model_frame>1</use_parent_model_frame>
      </axis>
    </joint>
    <link name='right_wheel'>
      <pose frame=''>0 -0.163 0.1 0 -0 1.5708</pose>
      <inertial>
        <pose frame=''>0 0 0 3.14159 1.57079 3.14159</pose>
        <mass>3.34</mass>
        <inertia>
          <ixx>0.00904583</ixx>
          <ixy>0</ixy>
          <ixz>0</ixz>
          <iyy>0.00904583</iyy>
          <iyz>0</iyz>
          <izz>0.0167</izz>
        </inertia>
      </inertial>
      <collision name='right_wheel_collision'>
        <pose frame=''>0 0 0 3.14159 1.57079 3.14159</pose>
        <geometry>
          <sphere>
            <radius>0.1</radius>
          </sphere>
        </geometry>
        <surface>
          <contact>
            <ode>
            <!--
              <kp>1e+08</kp>
              <min_depth>0.005</min_depth>
              -->
              <kp>10000000.0</kp>
              <kd>1.0</kd>
            </ode>
          </contact>
          <friction>
            <ode>
              <mu>1</mu>
              <mu2>1</mu2>
              <fdir1>0 0 1</fdir1>
            </ode>
          </friction>
        </surface>
      </collision>
      <visual name='right_wheel_visual'>
        <pose frame=''>0.071 0 0 -3.14159 0 -3.14159</pose>
        <geometry>
          <mesh>
            <scale>1 1 1</scale>
            <uri>model://TinyRobot/meshes/front_wheel.dae</uri>
          </mesh>
        </geometry>
      </visual>
      <gravity>1</gravity>
      <velocity_decay/>
    </link>
    <joint name='joint_tire_right' type='revolute'>
      <child>right_wheel</child>
      <parent>base_footprint</parent>
      <axis>
        <xyz>0 1 0</xyz>
        <limit>
          <lower>-1e+16</lower>
          <upper>1e+16</upper>
        </limit>
        <dynamics>
          <spring_reference>0</spring_reference>
          <spring_stiffness>0</spring_stiffness>
        </dynamics>
        <use_parent_model_frame>1</use_parent_model_frame>
      </axis>
    </joint>
    <static>0</static>

  </model>
</sdf>
