<?xml version="1.0"?>

<sdf version="1.6">
  <model name="HospitalRobot">

    <plugin name="slotcar" filename="libslotcar.so">

      <!-- Forward / Backward -->
      <nominal_drive_speed>0.7</nominal_drive_speed>
      <nominal_drive_acceleration>0.5</nominal_drive_acceleration>
      <!-- Theoretical no-slip limit with current suspension: 0.8 -->
      <max_drive_acceleration>0.75</max_drive_acceleration>

      <!-- Turning -->
      <nominal_turn_speed>0.3</nominal_turn_speed>
      <!-- Note: The official maximum turn acceleration value is 0.25, but that
           seems to be too small for the simulated WhiteRobot to do course
           corrections while driving, so it ends up swaying erratically. Using
           this larger value helps keep WhiteRobot's course stable. -->
      <nominal_turn_acceleration>1.5</nominal_turn_acceleration>
      <!-- Theoretical no-slip limit with current suspension: 2.166666... -->
      <max_turn_acceleration>2.0</max_turn_acceleration>

      <stop_distance>0.75</stop_distance>
      <stop_radius>0.75</stop_radius>

      <!-- Can the robot drive backwards -->
      <reversible>false</reversible>

      <!-- Battery params -->
      <nominal_voltage>24.0</nominal_voltage>
      <nominal_capacity>24.0</nominal_capacity>
      <charging_current>5.0</charging_current>

      <!-- Physical params -->
      <mass>70.0</mass>
      <inertia>40.0</inertia>
      <friction_coefficient>0.22</friction_coefficient>

      <!-- Power systems -->
      <nominal_power>20.0</nominal_power>

    </plugin>

    <link name="body">
      <pose>0 0 0 0 0 0</pose>

      <inertial>
        <pose>0 0 0.693 0 0 0</pose>
        <mass>170</mass>
        <inertia>
          <ixx>34.6605</ixx>
          <iyy>32.8369</iyy>
          <izz>13.0691</izz>
        </inertia>
      </inertial>

      <collision name="collision">
        <pose>0 0 0.7 0 0 0</pose>
        <geometry>
          <box>
            <size>0.7 0.7 1.4</size>
          </box>
        </geometry>
        <surface>
          <friction>
            <torsional>
              <coefficient>0.0</coefficient>
            </torsional>
            <ode>
              <mu>0.0</mu>
              <mu2>0.0</mu2>
            </ode>
            <bullet>
              <friction>0.0</friction>
              <friction2>0.0</friction2>
              <rolling_friction>0.0</rolling_friction>
            </bullet>
          </friction>
        </surface>
      </collision>

      <visual name="visual">
        <geometry>
          <mesh><uri>model://HospitalRobot/meshes/HospitalRobot.obj</uri></mesh>
        </geometry>
      </visual>
      <visual name="front_wheel_left">
      <pose>.17 -.21 .03 0 0 0</pose>
        <geometry>
          <mesh><uri>model://HospitalRobot/meshes/SmallWheel.obj</uri></mesh>
        </geometry>
      </visual>
      <visual name="back_wheel_left">
      <pose>-.24 -.21 .03 0 0 0</pose>
        <geometry>
          <mesh><uri>model://HospitalRobot/meshes/SmallWheel.obj</uri></mesh>
        </geometry>
      </visual>
      <visual name="front_wheel_right">
      <pose>.17 .21 .03 0 0 0</pose>
        <geometry>
          <mesh><uri>model://HospitalRobot/meshes/SmallWheel.obj</uri></mesh>
        </geometry>
      </visual>
      <visual name="back_wheel_right">
      <pose>-.24 .21 .03 0 0 0</pose>
        <geometry>
          <mesh><uri>model://HospitalRobot/meshes/SmallWheel.obj</uri></mesh>
        </geometry>
      </visual>
    </link>

    <link name="suspension_tire_left">
      <!-- This is a dummy link that's used to connect a suspension (prismatic
           joint) to the tire axis (revolute joint) -->
      <pose>0 .21 .06 0 0 0</pose>
      <inertial>
        <mass>1.00</mass>
        <inertia>
          <ixx>1.00</ixx>
          <iyy>1.00</iyy>
          <izz>1.00</izz>
        </inertia>
      </inertial>
    </link>

    <joint name="joint_suspension_tire_left" type="prismatic">
      <parent>body</parent>
      <child>suspension_tire_left</child>
      <axis>
        <xyz>0 0 1</xyz>
        <dynamics>
          <damping>500</damping>
          <spring_reference>-0.05</spring_reference>
          <spring_stiffness>2000</spring_stiffness>
        </dynamics>
      </axis>
      <physics>
        <ode>
          <implicit_spring_damper>true</implicit_spring_damper>
        </ode>
      </physics>
    </joint>

    <link name="tire_left">
      <pose>0 .21 .06 0 0 0</pose>
      <inertial>
        <pose>0 0 0 0 0 0</pose>
        <mass>5.0</mass>
        <inertia>
          <ixx>0.757897446874</ixx>
          <iyy>1.302975553365</iyy>
          <izz>0.757897446874</izz>
        </inertia>
      </inertial>
      <visual name="fat_wheel_left">
        <geometry>
          <mesh><uri>model://HospitalRobot/meshes/FatWheel.obj</uri></mesh>
        </geometry>
      </visual>
      <collision name="tire_left">
        <geometry>
          <sphere><radius>0.06137</radius></sphere>
        </geometry>
        <surface>
          <contact>
            <ode>
              <kp>10000000.0</kp>
              <kd>1.0</kd>
            </ode>
          </contact>
        </surface>
      </collision>
    </link>

    <joint name="joint_tire_left" type="revolute">
      <parent>suspension_tire_left</parent>
      <child>tire_left</child>
      <axis>
        <xyz>0 1 0</xyz>
      </axis>
    </joint>

    <link name="suspension_tire_right">
      <!-- This is a dummy link that's used to connect a suspension (prismatic
           joint) to the tire axis (revolute joint) -->
      <pose>0 -.21 .06 0 0 0</pose>
      <inertial>
        <mass>1.00</mass>
        <inertia>
          <ixx>1.00</ixx>
          <iyy>1.00</iyy>
          <izz>1.00</izz>
        </inertia>
      </inertial>
    </link>

    <joint name="joint_suspension_tire_right" type="prismatic">
      <parent>body</parent>
      <child>suspension_tire_right</child>
      <axis>
        <xyz>0 0 1</xyz>
        <dynamics>
          <damping>500</damping>
          <spring_reference>-0.05</spring_reference>
          <spring_stiffness>2000</spring_stiffness>
        </dynamics>
      </axis>
      <physics>
        <ode>
          <implicit_spring_damper>true</implicit_spring_damper>
        </ode>
      </physics>
    </joint>

    <link name="tire_right">
      <pose>0 -.21 .06 0 0 0</pose>
      <inertial>
        <pose>0 0 0 0 0 0</pose>
        <mass>5.0</mass>
        <inertia>
          <ixx>0.757897446874</ixx>
          <iyy>1.302975553365</iyy>
          <izz>0.757897446874</izz>
        </inertia>
      </inertial>
      <visual name="fat_wheel_right">
        <geometry>
          <mesh><uri>model://HospitalRobot/meshes/FatWheel.obj</uri></mesh>
        </geometry>
      </visual>
      <collision name="tire_right">
        <geometry>
          <sphere><radius>0.06137</radius></sphere>
        </geometry>
        <surface>
          <contact>
            <ode>
              <kp>10000000.0</kp>
              <kd>1.0</kd>
            </ode>
          </contact>
        </surface>
      </collision>
    </link>

    <joint name="joint_tire_right" type="revolute">
      <parent>suspension_tire_right</parent>
      <child>tire_right</child>
      <axis>
        <xyz>0 1 0</xyz>
      </axis>
    </joint>

  </model>
</sdf>
